<?xml version="1.0" ?>
<!-- =================================================================================== -->
<!-- |    This document was autogenerated by xacro from /home/parispoll/robot_ws/src/my_robot_description/urdf/my_robot.urdf.xacro | -->
<!-- |    EDITING THIS FILE BY HAND IS NOT RECOMMENDED                                 | -->
<!-- =================================================================================== -->
<robot name="my_robot">
  <!-- ================= -->
  <!-- Materials -->
  <!-- ================= -->
  <material name="green">
    <color rgba="0.2 0.8 0.2 1"/>
  </material>
  <material name="blue">
    <color rgba="0.2 0.2 0.8 1"/>
  </material>
  <material name="gray">
    <color rgba="0.6 0.6 0.6 1"/>
  </material>
  <!-- ================= -->
  <!-- Dummy root link -->
  <!-- ================= -->
  <link name="world_link"/>
  <joint name="world_to_base" type="fixed">
    <parent link="world_link"/>
    <child link="base_link"/>
    <origin rpy="0 0 0" xyz="0 0 0.9"/>
  </joint>
  <!-- ================= -->
  <!-- Base -->
  <!-- ================= -->
  <link name="base_link">
    <inertial>
      <origin xyz="0 0 0"/>
      <mass value="5.0"/>
      <inertia ixx="0.02083333333333334" ixy="0" ixz="0" iyy="0.041666666666666664" iyz="0" izz="0.05416666666666667"/>
    </inertial>
    <visual>
      <geometry>
        <box size="0.3 0.2 0.1"/>
      </geometry>
      <material name="gray"/>
    </visual>
  </link>
  <!-- ================= -->
  <!-- Upper body -->
  <!-- ================= -->
  <link name="link_1">
    <inertial>
      <origin xyz="0 0 0"/>
      <mass value="1.0"/>
      <inertia ixx="0.00041666666666666675" ixy="0" ixz="0" iyy="0.0035416666666666674" iyz="0" izz="0.0035416666666666674"/>
    </inertial>
    <visual>
      <geometry>
        <box size="0.2 0.05 0.05"/>
      </geometry>
      <material name="blue"/>
    </visual>
  </link>
  <joint name="joint_1" type="revolute">
    <parent link="base_link"/>
    <child link="link_1"/>
    <origin rpy="0 0 0" xyz="0 0 0.1"/>
    <axis xyz="0 0 1"/>
    <limit effort="10" lower="-1.57" upper="1.57" velocity="3"/>
  </joint>
  <!-- Thigh -->
  <link name="left_thigh">
    <inertial>
      <origin xyz="0 0 0"/>
      <mass value="1.0"/>
      <inertia ixx="0.005416666666666667" ixy="0" ixz="0" iyy="0.005416666666666667" iyz="0" izz="0.00041666666666666675"/>
    </inertial>
    <visual>
      <geometry>
        <box size="0.05 0.05 0.25"/>
      </geometry>
      <material name="green"/>
    </visual>
  </link>
  <joint name="left_hip_joint" type="revolute">
    <parent link="base_link"/>
    <child link="left_thigh"/>
    <origin rpy="0 0 0" xyz="0 0.1 -0.05"/>
    <axis xyz="1 0 0"/>
    <limit effort="20" lower="-1.0" upper="1.0" velocity="4"/>
  </joint>
  <!-- Shin -->
  <link name="left_shin">
    <inertial>
      <origin xyz="0 0 0"/>
      <mass value="0.8"/>
      <inertia ixx="0.004273333333333334" ixy="0" ixz="0" iyy="0.004273333333333334" iyz="0" izz="0.00021333333333333336"/>
    </inertial>
    <visual>
      <geometry>
        <box size="0.04 0.04 0.25"/>
      </geometry>
      <material name="blue"/>
    </visual>
  </link>
  <joint name="left_knee_joint" type="revolute">
    <parent link="left_thigh"/>
    <child link="left_shin"/>
    <origin rpy="0 0 0" xyz="0 0 -0.25"/>
    <axis xyz="1 0 0"/>
    <limit effort="20" lower="0.0" upper="2.2" velocity="4"/>
  </joint>
  <!-- Foot -->
  <link name="left_foot">
    <inertial>
      <origin xyz="0 0 0"/>
      <mass value="0.5"/>
      <inertia ixx="0.0006666666666666666" ixy="0" ixz="0" iyy="0.0003333333333333333" iyz="0" izz="0.0008666666666666666"/>
    </inertial>
    <collision>
      <origin xyz="0 0 0.02"/>
      <geometry>
        <box size="0.08 0.12 0.04"/>
      </geometry>
    </collision>
    <visual>
      <origin xyz="0 0 0.02"/>
      <geometry>
        <box size="0.08 0.12 0.04"/>
      </geometry>
      <material name="gray"/>
    </visual>
  </link>
  <joint name="left_ankle_joint" type="revolute">
    <parent link="left_shin"/>
    <child link="left_foot"/>
    <origin rpy="0 0 0" xyz="0 0 -0.25"/>
    <axis xyz="1 0 0"/>
    <limit effort="15" lower="-0.6" upper="0.6" velocity="4"/>
  </joint>
  <!-- Thigh -->
  <link name="right_thigh">
    <inertial>
      <origin xyz="0 0 0"/>
      <mass value="1.0"/>
      <inertia ixx="0.005416666666666667" ixy="0" ixz="0" iyy="0.005416666666666667" iyz="0" izz="0.00041666666666666675"/>
    </inertial>
    <visual>
      <geometry>
        <box size="0.05 0.05 0.25"/>
      </geometry>
      <material name="green"/>
    </visual>
  </link>
  <joint name="right_hip_joint" type="revolute">
    <parent link="base_link"/>
    <child link="right_thigh"/>
    <origin rpy="0 0 0" xyz="0 -0.1 -0.05"/>
    <axis xyz="1 0 0"/>
    <limit effort="20" lower="-1.0" upper="1.0" velocity="4"/>
  </joint>
  <!-- Shin -->
  <link name="right_shin">
    <inertial>
      <origin xyz="0 0 0"/>
      <mass value="0.8"/>
      <inertia ixx="0.004273333333333334" ixy="0" ixz="0" iyy="0.004273333333333334" iyz="0" izz="0.00021333333333333336"/>
    </inertial>
    <visual>
      <geometry>
        <box size="0.04 0.04 0.25"/>
      </geometry>
      <material name="blue"/>
    </visual>
  </link>
  <joint name="right_knee_joint" type="revolute">
    <parent link="right_thigh"/>
    <child link="right_shin"/>
    <origin rpy="0 0 0" xyz="0 0 -0.25"/>
    <axis xyz="1 0 0"/>
    <limit effort="20" lower="0.0" upper="2.2" velocity="4"/>
  </joint>
  <!-- Foot -->
  <link name="right_foot">
    <inertial>
      <origin xyz="0 0 0"/>
      <mass value="0.5"/>
      <inertia ixx="0.0006666666666666666" ixy="0" ixz="0" iyy="0.0003333333333333333" iyz="0" izz="0.0008666666666666666"/>
    </inertial>
    <collision>
      <origin xyz="0 0 0.02"/>
      <geometry>
        <box size="0.08 0.12 0.04"/>
      </geometry>
    </collision>
    <visual>
      <origin xyz="0 0 0.02"/>
      <geometry>
        <box size="0.08 0.12 0.04"/>
      </geometry>
      <material name="gray"/>
    </visual>
  </link>
  <joint name="right_ankle_joint" type="revolute">
    <parent link="right_shin"/>
    <child link="right_foot"/>
    <origin rpy="0 0 0" xyz="0 0 -0.25"/>
    <axis xyz="1 0 0"/>
    <limit effort="15" lower="-0.6" upper="0.6" velocity="4"/>
  </joint>
  <ros2_control name="GazeboSimSystem" type="system">
    <hardware>
      <plugin>gz_ros2_control/GazeboSimSystem</plugin>
    </hardware>
    <joint name="left_hip_joint">
      <command_interface name="position"/>
      <state_interface name="position"/>
      <state_interface name="velocity"/>
    </joint>
    <joint name="left_knee_joint">
      <command_interface name="position"/>
      <state_interface name="position"/>
      <state_interface name="velocity"/>
    </joint>
    <joint name="left_ankle_joint">
      <command_interface name="position"/>
      <state_interface name="position"/>
      <state_interface name="velocity"/>
    </joint>
    <joint name="right_hip_joint">
      <command_interface name="position"/>
      <state_interface name="position"/>
      <state_interface name="velocity"/>
    </joint>
    <joint name="right_knee_joint">
      <command_interface name="position"/>
      <state_interface name="position"/>
      <state_interface name="velocity"/>
    </joint>
    <joint name="right_ankle_joint">
      <command_interface name="position"/>
      <state_interface name="position"/>
      <state_interface name="velocity"/>
    </joint>
  </ros2_control>
  <gazebo>
    <plugin filename="libgz_ros2_control-system.so" name="gz_ros2_control::GazeboSimROS2ControlPlugin"/>
  </gazebo>
</robot>
